Workbook

Sheet 가정
A1: TAERIJAY 수익 시뮬레이션 — 가정(Assumptions)
A2: 기간: 2026-09-01 ~ 2026-12-31 (4개월, 121일) · 개인 홍보(유료광고 없음) · 채널: 유튜브·인스타그램·틱톡·구글/네이버 블로그
A4: ※ 파란 글씨 = 직접 입력하는 가정값. 시나리오 탭 계산은 전부 이 값들을 참조합니다.
A6: 1) 요금제 (pricing.astro 기준 실제 가격)
A7: 요금제 | B7: 월가격(USD) | C7: 비고
A8: BASIC (싱글) | B8: 19.99 | C8: 1채널, 1디바이스
A9: STANDARD (싱글) | B9: 29.99 | C9: 1채널, 2디바이스·2동접
A10: PRO (싱글) | B10: 39.99 | C10: 1채널, 3디바이스·3동접
A11: 더블(2채널 묶음) | B11: 34.99 | C11: protocol+mini 또는 red+green
A12: 토탈(5채널 전체) | B12: 99.99 | C12: 전 채널, 1디바이스
A14: 가중평균 결제단가 (ARPU, USD/월) — 시나리오별 입력
A15: 시나리오 | B15: 9월 | C15: 10월 | D15: 11월 | E15: 12월 | F15: 설명
A16: ① 최소 | B16: 19.99 | C16: 22 | D16: 24 | E16: 26 | F16: 초반엔 BASIC 위주, 서서히 STANDARD 섞임
A17: ② 평균 | B17: 24 | C17: 27 | D17: 29.99 | E17: 32 | F17: STANDARD 중심, 후반 더블 일부 유입
A18: ③ 최대 | B18: 27 | C18: 32 | D18: 35 | E18: 38 | F18: STANDARD~PRO, 더블/토탈 비중 증가
A19: ④ 대박 | B19: 29.99 | C19: 35 | D19: 42 | E19: 48 | F19: PRO+토탈 비중 확대, 입소문 프리미엄 전환
A22: 2) 채널별 월간 순방문(유니크) 도달 가정 — 시나리오별, 개인 운영 기준
A23: ※ 팔로워/구독자 수가 아니라 '실제 링크 클릭 → 사이트 방문'으로 이어지는 순방문 추정치입니다.
A24: 시나리오 | B24: 채널 | C24: 9월 방문 | D24: 10월 방문 | E24: 11월 방문 | F24: 12월 방문
A25: ① 최소 | B25: 유튜브(쇼츠+영상) | C25: 150 | D25: 300 | E25: 500 | F25: 700
B26: 인스타그램(릴스+피드) | C26: 200 | D26: 400 | E26: 650 | F26: 900
B27: 틱톡 | C27: 180 | D27: 350 | E27: 550 | F27: 750
B28: 블로그(구글+네이버) | C28: 100 | D28: 200 | E28: 320 | F28: 450
A29: ② 평균 | B29: 유튜브(쇼츠+영상) | C29: 400 | D29: 900 | E29: 1600 | F29: 2400
B30: 인스타그램(릴스+피드) | C30: 500 | D30: 1100 | E30: 1900 | F30: 2800
B31: 틱톡 | C31: 450 | D31: 1000 | E31: 1800 | F31: 2600
B32: 블로그(구글+네이버) | C32: 300 | D32: 650 | E32: 1100 | F32: 1600
A33: ③ 최대 | B33: 유튜브(쇼츠+영상) | C33: 900 | D33: 2500 | E33: 5000 | F33: 8500
B34: 인스타그램(릴스+피드) | C34: 1100 | D34: 3000 | E34: 6000 | F34: 10000
B35: 틱톡 | C35: 1000 | D35: 2800 | E35: 5800 | F35: 9500
B36: 블로그(구글+네이버) | C36: 600 | D36: 1500 | E36: 2800 | F36: 4200
A37: ④ 대박 | B37: 유튜브(쇼츠+영상) | C37: 2000 | D37: 15000 | E37: 35000 | F37: 55000
B38: 인스타그램(릴스+피드) | C38: 2500 | D38: 20000 | E38: 45000 | F38: 70000
B39: 틱톡 | C39: 2200 | D39: 18000 | E39: 42000 | F39: 65000
B40: 블로그(구글+네이버) | C40: 1200 | D40: 4000 | E40: 9000 | F40: 14000
A42: 3) 방문→결제 전환율 (Site Visit → Paid Signup)
A43: ※ 여행 정보 구독 서비스 특성상 즉시결제보다 '여행 임박 시점' 결제가 많아 방문 대비 낮은 전환율 가정. 언어확장(중/일) 시 도달모수 증가로 전환은 소폭 개선.
A44: 시나리오 | B44: 9월 | C44: 10월 | D44: 11월 | E44: 12월
A45: ① 최소 | B45: 0.004 | C45: 0.005 | D45: 0.006 | E45: 0.006
A46: ② 평균 | B46: 0.008 | C46: 0.01 | D46: 0.012 | E46: 0.013
...

Sheet 요약비교
A1: TAERIJAY 수익 시뮬레이션 — 시나리오 요약 비교
A2: 2026-09-01 ~ 2026-12-31 · 개인 SNS/블로그 홍보 기준(유료광고 미포함) · 한/영 우선, 11월부터 중국어, 12월부터 일본어 확장
A4: [1] 월별 매출 비교 (USD)
A5: 시나리오 | B5: 9월 | C5: 10월 | D5: 11월 | E5: 12월 | F5: 4개월 합계
A6: ① 최소 | B6: ='①최소'!B30 -> 59.97 | C6: ='①최소'!C30 -> 176 | D6: ='①최소'!D30 -> 408 | E6: ='①최소'!E30 -> 728 | F6: =SUM(B6:E6) -> 1371.97
A7: ② 평균 | B7: ='②평균'!B30 -> 312 | C7: ='②평균'!C30 -> 1242 | D7: ='②평균'!D30 -> 3298.9 | E7: ='②평균'!E30 -> 6432 | F7: =SUM(B7:E7) -> 11284.9
A8: ③ 최대 | B8: ='③최대'!B30 -> 1161 | C8: ='③최대'!C30 -> 5792 | D8: ='③최대'!D30 -> 17290 | E8: ='③최대'!E30 -> 39102 | F8: =SUM(B8:E8) -> 63345
A9: ④ 대박 | B9: ='④대박'!B30 -> 2369.21 | C9: ='④대박'!C30 -> 30135 | D9: ='④대박'!D30 -> 127974 | E9: ='④대박'!E30 -> 332448 | F9: =SUM(B9:E9) -> 492926.21
A12: [2] 월별 매출 비교 (KRW, ₩1,400/$ 환산)
A13: 시나리오 | B13: 9월 | C13: 10월 | D13: 11월 | E13: 12월 | F13: 4개월 합계
A14: ① 최소 | B14: =B6*1400 -> 83958 | C14: =C6*1400 -> 246400 | D14: =D6*1400 -> 571200 | E14: =E6*1400 -> 1019200 | F14: =SUM(B14:E14) -> 1920758
A15: ② 평균 | B15: =B7*1400 -> 436800 | C15: =C7*1400 -> 1738800 | D15: =D7*1400 -> 4618460 | E15: =E7*1400 -> 9004800 | F15: =SUM(B15:E15) -> 15798860
A16: ③ 최대 | B16: =B8*1400 -> 1625400 | C16: =C8*1400 -> 8108800 | D16: =D8*1400 -> 24206000 | E16: =E8*1400 -> 54742800 | F16: =SUM(B16:E16) -> 88683000
A17: ④ 대박 | B17: =B9*1400 -> 3316894 | C17: =C9*1400 -> 42189000 | D17: =D9*1400 -> 179163600 | E17: =E9*1400 -> 465427200 | F17: =SUM(B17:E17) -> 690096694
A20: [3] 12월말 기준 활성 유료 구독자 수
A21: 시나리오 | B21: 12월말 활성 구독자 | C21: 4개월 누적 신규가입
A22: ① 최소 | B22: ='①최소'!E29 -> 28 | C22: =SUM('①최소'!B15:E15) -> 38
A23: ② 평균 | B23: ='②평균'!E29 -> 201 | C23: =SUM('②평균'!B15:E15) -> 249
A24: ③ 최대 | B24: ='③최대'!E29 -> 1029 | C24: =SUM('③최대'!B15:E15) -> 1187
A25: ④ 대박 | B25: ='④대박'!E29 -> 6926 | C25: =SUM('④대박'!B15:E15) -> 7723
A28: [4] 4개월 총매출 한눈에 보기 (USD / KRW)
A29: 시나리오 | B29: 총매출 (USD) | C29: 총매출 (KRW)
A30: ① 최소 | B30: ='①최소'!B36 -> 1371.97 | C30: ='①최소'!B37 -> 1920758
A31: ② 평균 | B31: ='②평균'!B36 -> 11284.9 | C31: ='②평균'!B37 -> 15798860
A32: ③ 최대 | B32: ='③최대'!B36 -> 63345 | C32: ='③최대'!B37 -> 88683000
A33: ④ 대박 | B33: ='④대박'!B36 -> 492926.21 | C33: ='④대박'!B37 -> 690096694
A36: ※ 이 시뮬레이션은 실제 성과를 보장하지 않는 가정 기반 추정치입니다. '가정' 탭의 파란 글씨 입력값을 조정하면 전체 수치가 자동 재계산됩니다.
A37: ※ 결제 프로세서(Paddle 등) 수수료(약 5%), 부가세, 환율 변동은 반영되지 않은 총매출(Gross Revenue) 기준입니다.

Sheet ①최소
A1: TAERIJAY 수익 시뮬레이션 — ① 최소 시나리오
A2: 모든 입력값(파란 글�씨)은 '가정' 탭에서 관리됩니다. 이 시트는 계산만 수행합니다.
A4: 1) 채널별 월간 순방문자 (가정 탭 연동)
A5: 채널 | B5: 9월 | C5: 10월 | D5: 11월 | E5: 12월
A6: 유튜브(쇼츠+영상) | B6: =가정!C25 -> 150 | C6: =가정!D25 -> 300 | D6: =가정!E25 -> 500 | E6: =가정!F25 -> 700
A7: 인스타그램(릴스+피드) | B7: =가정!C26 -> 200 | C7: =가정!D26 -> 400 | D7: =가정!E26 -> 650 | E7: =가정!F26 -> 900
A8: 틱톡 | B8: =가정!C27 -> 180 | C8: =가정!D27 -> 350 | D8: =가정!E27 -> 550 | E8: =가정!F27 -> 750
A9: 블로그(구글+네이버) | B9: =가정!C28 -> 100 | C9: =가정!D28 -> 200 | D9: =가정!E28 -> 320 | E9: =가정!F28 -> 450
A10: 합계 방문자 | B10: =SUM(B6:B9) -> 630 | C10: =SUM(C6:C9) -> 1250 | D10: =SUM(D6:D9) -> 2020 | E10: =SUM(E6:E9) -> 2800
A12: 2) 방문→결제 전환율 및 월간 신규 유료가입
A13: 채널 | B13: 9월 | C13: 10월 | D13: 11월 | E13: 12월
A14: 전환율 (가정탭 연동) | B14: =가정!B45 -> 0.004 | C14: =가정!C45 -> 0.005 | D14: =가정!D45 -> 0.006 | E14: =가정!E45 -> 0.006
A15: 신규 유료가입자 수 | B15: =ROUND(B10*B14,0) -> 3 | C15: =ROUND(C10*C14,0) -> 6 | D15: =ROUND(D10*D14,0) -> 12 | E15: =ROUND(E10*E14,0) -> 17
A17: 3) 월간 Churn 반영 누적 활성 구독자
A18: 월 Churn율 (가정탭 연동) = ='가정'!B52
A19: 채널 | B19: 9월 | C19: 10월 | D19: 11월 | E19: 12월
A20: 기초 구독자 | B20: 0 | C20: =B23 -> 3 | D20: =C23 -> 8 | E20: =D23 -> 17
A21: 신규 유료가입자 | B21: =B15 -> 3 | C21: =C15 -> 6 | D21: =D15 -> 12 | E21: =E15 -> 17
A22: 해지자 수(기초×Churn율) | B22: =ROUND(B20*가정!$B$52,0) -> 0 | C22: =ROUND(C20*가정!$B$52,0) -> 1 | D22: =ROUND(D20*가정!$B$52,0) -> 3 | E22: =ROUND(E20*가정!$B$52,0) -> 6
A23: 기말 활성 구독자 | B23: =B20+B21-B22 -> 3 | C23: =C20+C21-C22 -> 8 | D23: =D20+D21-D22 -> 17 | E23: =E20+E21-E22 -> 28
A26: 4) 월 매출 (ARPU × 기말 활성 구독자)
A27: 구분 | B27: 9월 | C27: 10월 | D27: 11월 | E27: 12월 | F27: 4개월 합계
A28: ARPU (가정탭 연동, USD) | B28: =가정!B16 -> 19.99 | C28: =가정!C16 -> 22 | D28: =가정!D16 -> 24 | E28: =가정!E16 -> 26
A29: 기말 활성 구독자 | B29: =B23 -> 3 | C29: =C23 -> 8 | D29: =D23 -> 17 | E29: =E23 -> 28
A30: 월 매출 (USD) | B30: =B28*B29 -> 59.97 | C30: =C28*C29 -> 176 | D30: =D28*D29 -> 408 | E30: =E28*E29 -> 728 | F30: =SUM(B30:E30) -> 1371.97
A31: 월 매출 (KRW 환산, ₩1,400/$) | B31: =B30*1400 -> 83958 | C31: =C30*1400 -> 246400 | D31: =D30*1400 -> 571200 | E31: =E30*1400 -> 1019200 | F31: =SUM(B31:E31) -> 1920758
A33: 참고: 4개월 누적 신규 유료가입자 수 = | B33: =SUM(B15:E15) -> 38
A34: 참고: 12월말 기준 활성 구독자 수 = | B34: =E23 -> 28
A36: 4개월 총 매출 (USD) | B36: =F30 -> 1371.97
A37: 4개월 총 매출 (KRW) | B37: =F31 -> 1920758
A39: ※ Paddle/PG 수수료(약 5%) 및 부가세 등은 미차감한 총매출(Gross) 기준입니다.

Sheet ②평균
A1: TAERIJAY 수익 시뮬레이션 — ② 평균 시나리오
A2: 모든 입력값(파란 글�씨)은 '가정' 탭에서 관리됩니다. 이 시트는 계산만 수행합니다.
A4: 1) 채널별 월간 순방문자 (가정 탭 연동)
A5: 채널 | B5: 9월 | C5: 10월 | D5: 11월 | E5: 12월
A6: 유튜브(쇼츠+영상) | B6: =가정!C29 -> 400 | C6: =가정!D29 -> 900 | D6: =가정!E29 -> 1600 | E6: =가정!F29 -> 2400
A7: 인스타그램(릴스+피드) | B7: =가정!C30 -> 500 | C7: =가정!D30 -> 1100 | D7: =가정!E30 -> 1900 | E7: =가정!F30 -> 2800
A8: 틱톡 | B8: =가정!C31 -> 450 | C8: =가정!D31 -> 1000 | D8: =가정!E31 -> 1800 | E8: =가정!F31 -> 2600
A9: 블로그(구글+네이버) | B9: =가정!C32 -> 300 | C9: =가정!D32 -> 650 | D9: =가정!E32 -> 1100 | E9: =가정!F32 -> 1600
A10: 합계 방문자 | B10: =SUM(B6:B9) -> 1650 | C10: =SUM(C6:C9) -> 3650 | D10: =SUM(D6:D9) -> 6400 | E10: =SUM(E6:E9) -> 9400
A12: 2) 방문→결제 전환율 및 월간 신규 유료가입
A13: 채널 | B13: 9월 | C13: 10월 | D13: 11월 | E13: 12월
A14: 전환율 (가정탭 연동) | B14: =가정!B46 -> 0.008 | C14: =가정!C46 -> 0.01 | D14: =가정!D46 -> 0.012 | E14: =가정!E46 -> 0.013
A15: 신규 유료가입자 수 | B15: =ROUND(B10*B14,0) -> 13 | C15: =ROUND(C10*C14,0) -> 37 | D15: =ROUND(D10*D14,0) -> 77 | E15: =ROUND(E10*E14,0) -> 122
A17: 3) 월간 Churn 반영 누적 활성 구독자
A18: 월 Churn율 (가정탭 연동) = ='가정'!B53
A19: 채널 | B19: 9월 | C19: 10월 | D19: 11월 | E19: 12월
A20: 기초 구독자 | B20: 0 | C20: =B23 -> 13 | D20: =C23 -> 46 | E20: =D23 -> 110
A21: 신규 유료가입자 | B21: =B15 -> 13 | C21: =C15 -> 37 | D21: =D15 -> 77 | E21: =E15 -> 122
A22: 해지자 수(기초×Churn율) | B22: =ROUND(B20*가정!$B$53,0) -> 0 | C22: =ROUND(C20*가정!$B$53,0) -> 4 | D22: =ROUND(D20*가정!$B$53,0) -> 13 | E22: =ROUND(E20*가정!$B$53,0) -> 31
A23: 기말 활성 구독자 | B23: =B20+B21-B22 -> 13 | C23: =C20+C21-C22 -> 46 | D23: =D20+D21-D22 -> 110 | E23: =E20+E21-E22 -> 201
A26: 4) 월 매출 (ARPU × 기말 활성 구독자)
A27: 구분 | B27: 9월 | C27: 10월 | D27: 11월 | E27: 12월 | F27: 4개월 합계
A28: ARPU (가정탭 연동, USD) | B28: =가정!B17 -> 24 | C28: =가정!C17 -> 27 | D28: =가정!D17 -> 29.99 | E28: =가정!E17 -> 32
A29: 기말 활성 구독자 | B29: =B23 -> 13 | C29: =C23 -> 46 | D29: =D23 -> 110 | E29: =E23 -> 201
A30: 월 매출 (USD) | B30: =B28*B29 -> 312 | C30: =C28*C29 -> 1242 | D30: =D28*D29 -> 3298.9 | E30: =E28*E29 -> 6432 | F30: =SUM(B30:E30) -> 11284.9
A31: 월 매출 (KRW 환산, ₩1,400/$) | B31: =B30*1400 -> 436800 | C31: =C30*1400 -> 1738800 | D31: =D30*1400 -> 4618460 | E31: =E30*1400 -> 9004800 | F31: =SUM(B31:E31) -> 15798860
A33: 참고: 4개월 누적 신규 유료가입자 수 = | B33: =SUM(B15:E15) -> 249
A34: 참고: 12월말 기준 활성 구독자 수 = | B34: =E23 -> 201
A36: 4개월 총 매출 (USD) | B36: =F30 -> 11284.9
A37: 4개월 총 매출 (KRW) | B37: =F31 -> 15798860
A39: ※ Paddle/PG 수수료(약 5%) 및 부가세 등은 미차감한 총매출(Gross) 기준입니다.

Sheet ③최대
A1: TAERIJAY 수익 시뮬레이션 — ③ 최대 시나리오
A2: 모든 입력값(파란 글�씨)은 '가정' 탭에서 관리됩니다. 이 시트는 계산만 수행합니다.
A4: 1) 채널별 월간 순방문자 (가정 탭 연동)
A5: 채널 | B5: 9월 | C5: 10월 | D5: 11월 | E5: 12월
A6: 유튜브(쇼츠+영상) | B6: =가정!C33 -> 900 | C6: =가정!D33 -> 2500 | D6: =가정!E33 -> 5000 | E6: =가정!F33 -> 8500
A7: 인스타그램(릴스+피드) | B7: =가정!C34 -> 1100 | C7: =가정!D34 -> 3000 | D7: =가정!E34 -> 6000 | E7: =가정!F34 -> 10000
A8: 틱톡 | B8: =가정!C35 -> 1000 | C8: =가정!D35 -> 2800 | D8: =가정!E35 -> 5800 | E8: =가정!F35 -> 9500
A9: 블로그(구글+네이버) | B9: =가정!C36 -> 600 | C9: =가정!D36 -> 1500 | D9: =가정!E36 -> 2800 | E9: =가정!F36 -> 4200
A10: 합계 방문자 | B10: =SUM(B6:B9) -> 3600 | C10: =SUM(C6:C9) -> 9800 | D10: =SUM(D6:D9) -> 19600 | E10: =SUM(E6:E9) -> 32200
A12: 2) 방문→결제 전환율 및 월간 신규 유료가입
A13: 채널 | B13: 9월 | C13: 10월 | D13: 11월 | E13: 12월
A14: 전환율 (가정탭 연동) | B14: =가정!B47 -> 0.012 | C14: =가정!C47 -> 0.015 | D14: =가정!D47 -> 0.018 | E14: =가정!E47 -> 0.02
A15: 신규 유료가입자 수 | B15: =ROUND(B10*B14,0) -> 43 | C15: =ROUND(C10*C14,0) -> 147 | D15: =ROUND(D10*D14,0) -> 353 | E15: =ROUND(E10*E14,0) -> 644
A17: 3) 월간 Churn 반영 누적 활성 구독자
A18: 월 Churn율 (가정탭 연동) = ='가정'!B54
A19: 채널 | B19: 9월 | C19: 10월 | D19: 11월 | E19: 12월
A20: 기초 구독자 | B20: 0 | C20: =B23 -> 43 | D20: =C23 -> 181 | E20: =D23 -> 494
A21: 신규 유료가입자 | B21: =B15 -> 43 | C21: =C15 -> 147 | D21: =D15 -> 353 | E21: =E15 -> 644
A22: 해지자 수(기초×Churn율) | B22: =ROUND(B20*가정!$B$54,0) -> 0 | C22: =ROUND(C20*가정!$B$54,0) -> 9 | D22: =ROUND(D20*가정!$B$54,0) -> 40 | E22: =ROUND(E20*가정!$B$54,0) -> 109
A23: 기말 활성 구독자 | B23: =B20+B21-B22 -> 43 | C23: =C20+C21-C22 -> 181 | D23: =D20+D21-D22 -> 494 | E23: =E20+E21-E22 -> 1029
A26: 4) 월 매출 (ARPU × 기말 활성 구독자)
A27: 구분 | B27: 9월 | C27: 10월 | D27: 11월 | E27: 12월 | F27: 4개월 합계
A28: ARPU (가정탭 연동, USD) | B28: =가정!B18 -> 27 | C28: =가정!C18 -> 32 | D28: =가정!D18 -> 35 | E28: =가정!E18 -> 38
A29: 기말 활성 구독자 | B29: =B23 -> 43 | C29: =C23 -> 181 | D29: =D23 -> 494 | E29: =E23 -> 1029
A30: 월 매출 (USD) | B30: =B28*B29 -> 1161 | C30: =C28*C29 -> 5792 | D30: =D28*D29 -> 17290 | E30: =E28*E29 -> 39102 | F30: =SUM(B30:E30) -> 63345
A31: 월 매출 (KRW 환산, ₩1,400/$) | B31: =B30*1400 -> 1625400 | C31: =C30*1400 -> 8108800 | D31: =D30*1400 -> 24206000 | E31: =E30*1400 -> 54742800 | F31: =SUM(B31:E31) -> 88683000
A33: 참고: 4개월 누적 신규 유료가입자 수 = | B33: =SUM(B15:E15) -> 1187
A34: 참고: 12월말 기준 활성 구독자 수 = | B34: =E23 -> 1029
A36: 4개월 총 매출 (USD) | B36: =F30 -> 63345
A37: 4개월 총 매출 (KRW) | B37: =F31 -> 88683000
A39: ※ Paddle/PG 수수료(약 5%) 및 부가세 등은 미차감한 총매출(Gross) 기준입니다.

Sheet ④대박
A1: TAERIJAY 수익 시뮬레이션 — ④ 대박 시나리오
A2: 모든 입력값(파란 글�씨)은 '가정' 탭에서 관리됩니다. 이 시트는 계산만 수행합니다.
A4: 1) 채널별 월간 순방문자 (가정 탭 연동)
A5: 채널 | B5: 9월 | C5: 10월 | D5: 11월 | E5: 12월
A6: 유튜브(쇼츠+영상) | B6: =가정!C37 -> 2000 | C6: =가정!D37 -> 15000 | D6: =가정!E37 -> 35000 | E6: =가정!F37 -> 55000
A7: 인스타그램(릴스+피드) | B7: =가정!C38 -> 2500 | C7: =가정!D38 -> 20000 | D7: =가정!E38 -> 45000 | E7: =가정!F38 -> 70000
A8: 틱톡 | B8: =가정!C39 -> 2200 | C8: =가정!D39 -> 18000 | D8: =가정!E39 -> 42000 | E8: =가정!F39 -> 65000
A9: 블로그(구글+네이버) | B9: =가정!C40 -> 1200 | C9: =가정!D40 -> 4000 | D9: =가정!E40 -> 9000 | E9: =가정!F40 -> 14000
A10: 합계 방문자 | B10: =SUM(B6:B9) -> 7900 | C10: =SUM(C6:C9) -> 57000 | D10: =SUM(D6:D9) -> 131000 | E10: =SUM(E6:E9) -> 204000
A12: 2) 방문→결제 전환율 및 월간 신규 유료가입
A13: 채널 | B13: 9월 | C13: 10월 | D13: 11월 | E13: 12월
A14: 전환율 (가정탭 연동) | B14: =가정!B48 -> 0.01 | C14: =가정!C48 -> 0.014 | D14: =가정!D48 -> 0.018 | E14: =가정!E48 -> 0.022
A15: 신규 유료가입자 수 | B15: =ROUND(B10*B14,0) -> 79 | C15: =ROUND(C10*C14,0) -> 798 | D15: =ROUND(D10*D14,0) -> 2358 | E15: =ROUND(E10*E14,0) -> 4488
A17: 3) 월간 Churn 반영 누적 활성 구독자
A18: 월 Churn율 (가정탭 연동) = ='가정'!B55
A19: 채널 | B19: 9월 | C19: 10월 | D19: 11월 | E19: 12월
A20: 기초 구독자 | B20: 0 | C20: =B23 -> 79 | D20: =C23 -> 861 | E20: =D23 -> 3047
A21: 신규 유료가입자 | B21: =B15 -> 79 | C21: =C15 -> 798 | D21: =D15 -> 2358 | E21: =E15 -> 4488
A22: 해지자 수(기초×Churn율) | B22: =ROUND(B20*가정!$B$55,0) -> 0 | C22: =ROUND(C20*가정!$B$55,0) -> 16 | D22: =ROUND(D20*가정!$B$55,0) -> 172 | E22: =ROUND(E20*가정!$B$55,0) -> 609
A23: 기말 활성 구독자 | B23: =B20+B21-B22 -> 79 | C23: =C20+C21-C22 -> 861 | D23: =D20+D21-D22 -> 3047 | E23: =E20+E21-E22 -> 6926
A26: 4) 월 매출 (ARPU × 기말 활성 구독자)
A27: 구분 | B27: 9월 | C27: 10월 | D27: 11월 | E27: 12월 | F27: 4개월 합계
A28: ARPU (가정탭 연동, USD) | B28: =가정!B19 -> 29.99 | C28: =가정!C19 -> 35 | D28: =가정!D19 -> 42 | E28: =가정!E19 -> 48
A29: 기말 활성 구독자 | B29: =B23 -> 79 | C29: =C23 -> 861 | D29: =D23 -> 3047 | E29: =E23 -> 6926
A30: 월 매출 (USD) | B30: =B28*B29 -> 2369.21 | C30: =C28*C29 -> 30135 | D30: =D28*D29 -> 127974 | E30: =E28*E29 -> 332448 | F30: =SUM(B30:E30) -> 492926.21
A31: 월 매출 (KRW 환산, ₩1,400/$) | B31: =B30*1400 -> 3316894 | C31: =C30*1400 -> 42189000 | D31: =D30*1400 -> 179163600 | E31: =E30*1400 -> 465427200 | F31: =SUM(B31:E31) -> 690096694
A33: 참고: 4개월 누적 신규 유료가입자 수 = | B33: =SUM(B15:E15) -> 7723
A34: 참고: 12월말 기준 활성 구독자 수 = | B34: =E23 -> 6926
A36: 4개월 총 매출 (USD) | B36: =F30 -> 492926.21
A37: 4개월 총 매출 (KRW) | B37: =F31 -> 690096694
A39: ※ Paddle/PG 수수료(약 5%) 및 부가세 등은 미차감한 총매출(Gross) 기준입니다.
